Workbook

Sheet Patientenübersicht
A1: Spalte1 | B1: Name | C1: Geburtsdatum | D1: Scandatum | E1: Indikation | F1: Datum 2. FAPI PET/CT | G1: Datum 3. FAPI PET/CT | H1: Datum 4. FAPI PET/CT | I1: Datum 5. FAPI PET/CT | J1: Datum 6. FAPI PET/CT | K1: Datum 7. FAPI PET | L1: Datum 8. FAPI PET | M1: Datum 9. FAPI PET | N1: Datum 1. FDG PET | O1: Datum 2. FDG PET | P1: Ergebnis
A2: 103 | B2: Pietzsch, Michaela | C2: 28533 | D2: 09.03.2020 Spondylarthropathie
A3: 800 | B3: Gaal, Ronja | C3: 36731 | D3: 46368 | E3: Axiale Spondylarthropathie | F3: 46099 | G3: POLARIS
A4: 801 | B4: Unlütürk, aydan | C4: 32242 | D4: 46361 | E4: Axiale Spondylarthropathie | F4: 46099 | G4: POLARIS
A5: 875 | B5: Dülger, Göksel | C5: 23640 | D5: 46230 | E5: Unklare Pannikulitis | G5: Pannikulitis nur Flau FAPI positiv, Unklarer FAP positiver Fokus im rechten Obb
A6: 876 | B6: Schellmann, Nadine | C6: 31390 | D6: 46230 | E6: PsA | G6: unauffällig
A7: 874 | B7: Schlüter, Tim | C7: 30283 | D7: 46227 | E7: V.a. GvHD
A8: 872 | B8: Biermann-Jäckel, Ulrike | C8: 24654 | D8: 46223 | E8: Therapierefraktäre ILD | G8: LK mediastinal und epigastrisch, pulmonal nur flau FAPI positiv
A9: 869 | B9: Müller-Liesaus, Christine | C9: 30928 | D9: 46218 | E9: SSC | G9: Kräftig Bipulmonal
A10: 870 | B10: Brenner, Norbert | C10: 22232 | D10: 46218 | E10: NET Tumor vor RLT | G10: Kräftige FAPI Speicherung intratumoral, RLT als Therapieoption
A11: 871 | B11: Albad, Manal | C11: 31660 | D11: 46218 | E11: Polyarthralgien | G11: Myositisverdacht, einzelnen Sehnen im Fußbreich
A12: 867 | B12: Brendel,Reinhold | C12: 23900 | D12: 46213 | E12: IgG4 | G12: V.a. Pancreaskopf-CA, FDG aus Vorjahr negativ
A13: 868 | B13: Nase,Karin | C13: 21319 | D13: 46213 | E13: Ösophagus-CA | G13: Primarius und LK Filiae thorakal
A14: 865 | B14: Haas, Christian | C14: 25689 | D14: 46211 | E14: POLARIS, PsA | G14: V.a. sehenassoziiert in den Händen und Füßen
A15: 864 | B15: Baran, Bernd | C15: 25792 | D15: 46209 | E15: SpA externer Patient | G15: extern, mehrere Ansatzsehnen, v.a. Hände und Füße
A16: 863 | B16: Serexhe, Bernhard | C16: 18475 | D16: 46206 | E16: SSc unter Teclistamab | G16: Ausgeprägt bds. Pulmonal
A17: 866 | B17: Langer, Petra | C17: 28737 | D17: 46206 | E17: Endometriose | G17: Herd ventral des Uterus
A18: 861 | B18: Herdegen, Rainer | C18: 20663 | D18: 46202 | E18: Solitärer Fibröser Tumor Thorax | G18: Kräftige Anreicherung Pancreas, schwächer intratumoral
A19: 862 | B19: Barthelmes, Sandra | C19: 27696 | D19: 46202 | E19: Anti-Synthetase Syndrom
A20: 859 | B20: Müller, Artur | C20: 33610 | D20: 46199 | E20: SpA | G20: unauffällig, PET/MRT
A21: 860 | B21: Kainz, Karl | C21: 25024 | D21: 46199 | E21: Statin induzierte Myositis | G21: auffällig ischiocrurale Muskulatur
A22: 858 | B22: Meier, Christian | C22: 37204 | D22: 46197 | E22: SpA | G22: POLARIS, kräftig FAPI positive Sakroilitis
A23: 857 | B23: Fabrizius, Angelika | C23: 23242 | D23: 46195 | E23: Refrakträre Polyarthritis | G23: multifokale FAPI positive Gelenke, große und kleine Gelenke
A24: 853 | B24: Pickel-Schmitt, Margit | C24: 24864 | D24: 46192 | E24: RA unter MTX | G24: nur Hände und Ellenbogen, mehrere Gelenke betroffen, u.a. Olecranon rechts
A25: 854 | B25: Fichtner, Richard | C25: 24971 | D25: 46192 | E25: Seropostive RA | G25: extrem auffälliger Befund mit Befall Hände, Füße und deutlich Kniegelenk bds. Unklare Lymphadenopathie thorakal
A26: 855 | B26: Krause,Andrea | C26: 29551 | D26: 46192 | E26: Endometriose | G26: V.a. Herde pararektal
A27: 856 | B27: Florova, Martina | C27: 33493 | D27: 46192 | E27: Endometriose | G27: V.a. Herd parauterin
A28: 852 | B28: Kautny, Jürgen | C28: 23881 | D28: 46188 | E28: IgG4 Retorperitonealfibrose | G28: unauffällig
A29: 849 | B29: Satici, Levent | C29: 41536 | D29: 46185 | E29: Fokussuche Hypereosinophile | G29: unauffällig
A30: 850 | B30: Janetzke, Tabea | C30: 36591 | D30: 46185 | E30: Mischkollagenose | G30: unauffällig
A31: 851 | B31: Voigt, Bernd-Michael | C31: 23332 | D31: 46185 | E31: Myositis | G31: unauffällig
... A53: 828 | B53: Oleszak,Christian | C53: 35059 | D53: 46139 | E53: CED-assoziierte SpA | G53: Handgelenk rechts und Kniegelenk rechts, sehr flau
A54: 824 | B54: Heilemann, Michael | C54: 27884 | D54: 46138 | E54: PsA | F54: 46226 | G54: POLARIS, Kniegelenk links, linkes OSG, weitere multifokale Gelenke, Rippenserienfraktur bds.
A55: 825 | B55: Dengler, Maria-Sophie | C55: 36029 | D55: 46138 | E55: SpA | G55: FAPI positive Sakroilitiis
A56: 822 | B56: Wehrfitz, Jürgen | C56: 22361 | D56: 46132 | E56: Bronchialkarzinom Oberlappen links | G56: FAPI positiv mit LK Filiae, reaktiv entlang Aortenprothese
A57: 823 | B57: Schmidt, Ottilie | C57: 23508 | D57: 46132 | E57: Sjögren-Syndrom | G57: unauffällig
A58: 819 | B58: Eischer, Erika | C58: 17083 | D58: 46129 | E58: Pankreas-CA | G58: Leberfiliae, disseminierte Peritonealkarzinose, PET/MRT, LK Mammaria Stromgebiet rechts
A59: 820 | B59: Obemeyer, Andrea | C59: 26392 | D59: 46129 | E59: Endometriose | G59: unauffällig
A60: 821 | B60: Richter, Karina | C60: 33009 | D60: 46129 | E60: SpA | G60: unauffällig
A61: 817 | B61: Reintanz, Kathrin | C61: 29839 | D61: 46127 | E61: Autoinflammatorisches Syndrom | G61: unauffällig
...

Sheet Hayk Patienten
F11: Unauffällig
F12: Unauffällig
F13: Unauffällig
F14: Unauffällig
F15: Unauffällig

Sheet POLARIS
A3: No | B3: Name, Vorname | C3: DoB | D3: Scandate | E3: Scandate | J3: Scandate Follow-Up
A5: 1 | B5: Nink, Axel | C5: 19176 | D5: 45947 | G5: aus Studie ausgeschlossen
A6: 2 | B6: Kraus, Helga | C6: 20959 | D6: 45968 | E6: POLARIS, PsA | J6: 46064
A7: 4 | B7: Schott, Kerstin | C7: 23397 | D7: 45978 | E7: PsA | F7: Stammskelett FAPI positiv | J7: 46064
A8: 5 | B8: Ünlütürk, Ayhan | C8: 32242 | D8: 45996 | E8: SpA, Sakrolilitis, Pancreasanreicherung
A9: 7 | B9: Appel, Alexander | C9: 25961 | D9: 46071 | E9: PsA
A10: 8 | B10: Stark, Andrea | C10: 27712 | D10: 46078 | E10: PsA
A11: 9 | B11: Reddersen, Hans-Joachim | C11: 27275 | D11: 46106 | E11: PsA
A12: 10 | B12: Lang,Werner | C12: 25689 | D12: 46112 | E12: POLARIS, PsA | G12: Sprunggelenk links, FAPI positiver Lungenrundherd
A13: 11 | B13: Emck Tröger, Geert | C13: 34183 | D13: 46112 | E13: POLARIS, PsA | G13: Interspinal Höhe BWK 1-BWK4, Kniegelenk bds., Tendinitis rechtsbetont in beiden Füßen, peripankreatische Weichgewebsverdichtung
A14: 12 | B14: Matkovskyi, Mykola | C14: 29267 | D14: 46122 | E14: POLARIS, PsA

Sheet PET-MRT
A1: Nummer | B1: Name | C1: DoB | D1: Scandate | E1: Scanrange
A3: 1 | B3: Einicke-Merker, Tanja | C3: 26044 | D3: 45959 | E3: Hände | G3: auffällig, Handgelenk
A4: 2 | B4: Erdem, Ahmet | C4: 33966 | D4: 45959 | E4: ISG&LWS | G4: Sakroilitiis
A5: 3 | B5: Babayev, Shahriyar | C5: 32538 | D5: 45966 | E5: TK und WS | G5: unauffällig
A6: 4 | B6: Gömmel, Erwin | C6: 23733 | D6: 45966 | E6: Hände beiderseits | G6: auffällig, Handgelenk
A7: 5 | B7: Meyer, Gerhard | C7: 19790 | D7: 45994 | E7: Hände beiderseits | G7: auffällig, Synovialitis links, FAPI negative Erosion Digitus III links, angrenzende FAPI positive Synovialitis
A8: 6 | B8: Trivuncevic, Ruza | C8: 18726 | D8: 45994 | E8: UA und TK | G8: Sarkom Unterarm links und ergänzender GK
A9: 7 | B9: Chubych, Oryna | C9: 33476 | D9: 46050 | E9: Unterschenkel und Hände | G9: Fasziitis, sehr Auffällig V.a. Unterschenkel, gute Übereinstimmung STIR Sequenz
A10: 8 | B10: Lang, Wolfgang | C10: 14035 | D10: 45952 | E10: Körperstamm, Hände und Wirbelsäule | G10: sehr auffällig
A11: 9 | B11: Birner, Carmen | C11: 22148 | D11: 46066 | E11: Endometriose | G11: fokale Läsion am Sigma

Sheet FAPI Patienten IgG4 FAPI 46
B3: Name | C3: Geburtsdatum | D3: Scandatum | E3: Indikation | F3: Datum 2. FAPI PET/CT | G3: Datum 3. FAPI PET/CT | H3: Datum 4. FAPI PET/CT | I3: Datum 5. FAPI PET/CT | J3: Datum 6. FAPI PET/CT | K3: Datum 3. FAPI PET/CT
B6: Rieger, Iris | C6: 23687 | D6: 44967 | E6: IgG4-Syndrom
B7: Puff, Daniela | C7: 28626 | D7: 44981 | E7: IgG4-Syndrom
B8: Feigt,Katja | C8: 23945 | D8: 45121 | E8: IgG4-Syndrom
B9: Gelhaar,Peter | C9: 23371 | D9: 45177 | E9: IgG4-Syndrom
B10: Meier,Roland | C10: 21872 | D10: 45369 | E10: IgG4-Syndrom
B11: Eisenmeier, Reinhard | C11: 22498 | D11: 45401 | E11: IgG4 Erkrankung | F11: FDG PET zum Vgl. vorliegend 06/2023
B12: Muni, Guiseppe | C12: 17341 | D12: 45453 | E12: IgG4
B13: Astorino,Filomena | C13: 20930 | D13: 45471 | E13: IgG4
B14: Mützel,Wilfried | C14: 20804 | D14: 45499 | E14: IgG 4-Syndrom
B15: Neukam, Wolfgang | C15: 23360 | D15: 45537 | E15: IgG4 Syndrom
B16: Geistlehner, Peter | C16: 21438 | D16: 45551 | E16: IgG4 Syndrom
B17: Bergmann, Rena | C17: 20293 | D17: 45565 | E17: IgG4
B18: Bützow, Sven | C18: 25672 | D18: 45590 | E18: IgG4
B19: Ott, Stephan | C19: 31026 | D19: 45618 | E19: IgG4 Erkrankung
B23: FAPI 04
B25: Berisha, Astrit | C25: 31446 | D25: 43451 | E25: IgG 4-Syndrom | F25: 43717 | G25: 44791
B26: Hos, Mete | C26: 26816 | D26: 43493 | E26: IgG 4-Syndrom | F26: 43689 | G26: 45523
B27: Seffert, Gerda | C27: 12290 | D27: 43507 | E27: IgG 4-Syndrom
B28: Kraus, Andreas | C28: 19725 | D28: 43507 | E28: IgG 4-Syndrom | F28: 43745
B29: Lederer, Janina | C29: 33555 | D29: 43514 | E29: IgG 4-Syndrom
B30: Janosch, Vera | C30: 21725 | D30: 43521 | E30: IgG-4-Syndrom | F30: 43773 | G30: 44883
B31: Meier, Roland | C31: 21872 | D31: 43528 | E31: IgG-4-Syndrom | F31: 43759 | G31: 45131
B32: Thal, Hans-Günther | C32: 21814 | D32: 43528 | E32: IgG-4-Syndrom
B33: Kollorz, Uwe | C33: 24925 | D33: 43605 | E33: IgG 4-Syndrom | F33: 43766 | G33: 44424 | H33: 44907 | I33: 45264 | J33: 45537
B34: Zipfel, Josef | C34: 20420 | D34: 43647 | E34: IgG 4-Syndrom | F34: 43773
B35: Kohles, Cathrin | C35: 30190 | D35: 43752 | E35: IgG 4-Syndrom | F35: 44284 | G35: 44522
B36: Frommberger, Volker | C36: 24050 | D36: 43801 | E36: IgG4-Syndrom
B37: Sell, Dieter | C37: 22558 | D37: 43903 | E37: IgG-4/Riedel Struma
B38: Thun, Wolfgang | C38: 20474 | D38: 43976 | E38: IgG 4-Syndrom | F38: 44400 | G38: 44802 | H38: 45593
B39: Reubekeul, Axel | C39: 20092 | D39: 44001 | E39: IgG 4-Syndrom
B40: Stief, Christa | C40: 15713 | D40: 44050 | E40: IgG-4 Syndrom
B41: Steinhäußer, Mathias | C41: 31678 | D41: 44081 | E41: IgG-4 Syndrom
B42: Ringl, Hans-Jürgen | C42: 22660 | D42: 44099 | E42: IgG-4 Syndrom | F42: 44890
B43: Schürrlein, Gerhard | C43: 15153 | D43: 44116 | E43: IgG-4 Syndrom
B44: Palaczynski, Ireneusz | C44: 23421 | D44: 44354 | E44: IgG-4 Syndrom
B45: Römer, Carmen | C45: 25245 | D45: 44445 | E45: IgG-4 Syndrom
B46: Schiewe, Harry | C46: 15879 | D46: 44459 | E46: IgG-4 Syndrom | F46: 44540 | G46: 45131 | H46: 45411
B47: Emmerich, Rudolf | C47: 20047 | D47: 44473 | E47: IgG-4 Syndrom
B48: Muric, Ramona | C48: 20935 | D48: 44480 | E48: IgG-4 Syndrom
...

Sheet IgG-4
C1: Geburtsdatum | D1: Datum 1. FAPI | E1: Datum 2. FAPI | F1: Datum 1. FDG | G1: Datum 2. FDG | H1: Number of lesions | I1: Location | J1: 1. FDG SUVmax | K1: SUVpeak | L1: SUVmean | M1: MAV | N1: TLG | P1: 1. FAPI SUVmax | Q1: SUVpeak | R1: SUVmean | S1: MAV | T1: TL-FAPI | V1: 2. FDG SUVmax | W1: SUVpeak | X1: SUVmean | Y1: MAV | Z1: TLG | AB1: 2. FAPI SUVmax | AC1: SUVpeak | AD1: SUVmean | AE1: MAV | AF1: TL-FAPI | AI1: ='Auswertung IgG 4'!W1 -> TBR FAPI | AK1: TBR FDG
A2: 1 | B2: Berisha, Astrit | C2: 31446 | D2: 43451 | E2: 43717 | F2: 43551 | G2: 43718 | H2: 1 | I2: links retroperitoneal mit Kontakt zur li Nebenniere | J2: 8.1 | K2: 5.7 | L2: 4.8 | M2: 4.2 | N2: =(L2*M2) -> 20.16 | P2: 9.7 | Q2: 6.6 | R2: 5.2 | S2: 7.4 | T2: =(R2*S2) -> 38.48 | V2: 0 | W2: 0 | X2: 0 | Y2: 0 | Z2: 0 | AB2: 6.1 | AC2: 4.6 | AD2: 3.5 | AE2: 8.6 | AF2: =(AD2*AE2) -> 30.1 | AI2: ='Auswertung IgG 4'!W2 -> 10.777778 | AK2: 4.7647059
AI3: ='Auswertung IgG 4'!W3 -> 0
A4: 2 | B4: Kraus, Andreas | C4: 19725 | D4: 43507 | E4: 43745 | F4: 43501 | G4: 43746 | H4: 1 | I4: Aorta abdominalis | J4: 5 | K4: 4 | L4: 2.7 | M4: 37.6 | N4: =(L4*M4) -> 101.52 | P4: 7.1 | Q4: 5.5 | R4: 3.7 | S4: 29.9 | T4: =(R4*S4) -> 110.63 | V4: 0 | W4: 0 | X4: 0 | Y4: 0 | Z4: 0 | AB4: 4.2 | AC4: 2.8 | AD4: 2.2 | AE4: 14.8 | AF4: =(AD4*AE4) -> 32.56 | AI4: ='Auswertung IgG 4'!W4 -> 8.875 | AK4: 3.3333333
AI5: ='Auswertung IgG 4'!W5 -> 0
A6: 3 | B6: Kollorz, Uwe | C6: 24925 | D6: 43605 | E6: 43766 | F6: 43606 | G6: 43767 | H6: 1 | I6: Intracerebral occipital | J6: 12.8 | K6: 10.2 | L6: 8.9 | M6: 3.5 | N6: =(L6*M6) -> 31.15 | P6: 10.3 | Q6: 4.4 | R6: 6.5 | S6: 1.8 | T6: =(R6*S6) -> 11.7 | V6: 0 | W6: 0 | X6: 0 | Y6: 0 | Z6: 0 | AB6: 1.8 | AC6: 1.2 | AD6: 1.2 | AE6: 1.6 | AF6: =(AD6*AE6) -> 1.92 | AI6: ='Auswertung IgG 4'!W6 -> 9.8877551 | AK6: 3.3846154
H7: 1 | I7: Intracerebral rechts temporooccipital | P7: 3.3 | Q7: 1.4 | R7: 2.1 | S7: 1.1 | T7: =(R7*S7) -> 2.31 | V7: nd | W7: nd | X7: nd | Y7: nd | Z7: nd | AB7: 1.1 | AC7: 0.7 | AD7: 0.7 | AE7: 0.9 | AF7: =(AD7*AE7) -> 0.63 | AI7: ='Auswertung IgG 4'!W7 -> 0
H8: 1 | I8: Sinus cavernosus | J8: 14.4 | K8: 10.3 | L8: 8 | M8: 8.3 | N8: =(L8*M8) -> 66.4 | P8: 11.9 | Q8: 7.7 | R8: 6.8 | S8: 5.9 | T8: =(R8*S8) -> 40.12 | V8: 0 | W8: 0 | X8: 0 | Y8: 0 | Z8: 0 | AB8: 3.7 | AC8: 2.6 | AD8: 2.1 | AE8: 5.9 | AF8: =(AD8*AE8) -> 12.39 | AI8: ='Auswertung IgG 4'!W8 -> 0
H9: 1 | I9: Aortenbogen | J9: 8.6 | K9: 5.9 | L9: 4.7 | M9: 21.5 | N9: =(L9*M9) -> 101.05 | P9: 11.3 | Q9: 7.7 | R9: 6.3 | S9: 23.6 | T9: =(R9*S9) -> 148.68 | V9: 2.7 | W9: 2.3 | X9: 1.8 | Y9: 4.5 | Z9: =(X9*Y9) -> 8.1 | AB9: 4.2 | AC9: 3.1 | AD9: 2.3 | AE9: 18 | AF9: =(AD9*AE9) -> 41.4 | AI9: ='Auswertung IgG 4'!W9 -> 0
H10: 1 | I10: Aorta thoracalis | J10: 7.7 | K10: 4.8 | L10: 3.8 | M10: 26 | N10: =(L10*M10) -> 98.8 | P10: 8.8 | Q10: 6.4 | R10: 4.6 | S10: 49.9 | T10: =(R10*S10) -> 229.54 | V10: 0 | W10: 0 | X10: 0 | Y10: 0 | Z10: 0 | AB10: 4.1 | AC10: 3 | AD10: 2.2 | AE10: 19.1 | AF10: =(AD10*AE10) -> 42.02 | AI10: ='Auswertung IgG 4'!W10 -> 0
H11: 1 | I11: Aorta abdominalis | J11: 4.3 | K11: 2.9 | L11: 2.2 | M11: 31 | N11: =(L11*M11) -> 68.2 | P11: 7.6 | Q11: 5 | R11: 3.9 | S11: 15.3 | T11: =(R11*S11) -> 59.67 | V11: 0 | W11: 0 | X11: 0 | Y11: 0 | Z11: 0 | AB11: 3 | AC11: 2.4 | AD11: 1.6 | AE11: 11 | AF11: =(AD11*AE11) -> 17.6 | AI11: ='Auswertung IgG 4'!W11 -> 0
H12: 1 | I12: Art. Iliaca rechts | J12: 2.9 | K12: 2.3 | L12: 2.1 | M12: 2.4 | N12: =(L12*M12) -> 5.04 | P12: 5.1 | Q12: 3.2 | R12: 2.7 | S12: 4.7 | T12: =(R12*S12) -> 12.69 | V12: 0 | W12: 0 | X12: 0 | Y12: 0 | Z12: 0 | AB12: 1.8 | AC12: 1.6 | AD12: 1.5 | AE12: 2.2 | AF12: =(AD12*AE12) -> 3.3 | AI12: ='Auswertung IgG 4'!W12 -> 0
H13: 1 | I13: Art. Iliaca links | J13: 3.1 | K13: 2.7 | L13: 2.2 | M13: 3.3 | N13: =(L13*M13) -> 7.26 | P13: 6.8 | Q13: 4.6 | R13: 3.9 | S13: 4.3 | T13: =(R13*S13) -> 16.77 | V13: 0 | W13: 0 | X13: 0 | Y13: 0 | Z13: 0 | AB13: 2.5 | AC13: 2 | AD13: 1.4 | AE13: 2.1 | AF13: =(AD13*AE13) -> 2.94 | AI13: ='Auswertung IgG 4'!W13 -> 0
H14: 1 | I14: Art. femoralis links | J14: 2.9 | K14: 1.9 | L14: 2 | M14: 1 | N14: =(L14*M14) -> 2 | P14: 2.6 | Q14: 2.1 | R14: 1.9 | S14: 1.9 | T14: =(R14*S14) -> 3.61 | V14: 0 | W14: 0 | X14: 0 | Y14: 0 | Z14: 0 | AB14: 1.4 | AC14: 1.2 | AD14: 1.1 | AE14: 1.2 | AF14: =(AD14*AE14) -> 1.32 | AI14: ='Auswertung IgG 4'!W14 -> 0
H15: 1 | I15: Art. femoralis rechts | J15: 2.5 | K15: 1.9 | L15: 2 | M15: 1.1 | N15: =(L15*M15) -> 2.2 | P15: 3.6 | Q15: 2.4 | R15: 2.2 | S15: 2.8 | T15: =(R15*S15) -> 6.16 | V15: 0 | W15: 0 | X15: 0 | Y15: 0 | Z15: 0 | AB15: 2.1 | AC15: 2 | AD15: 1.9 | AE15: 2.1 | AF15: =(AD15*AE15) -> 3.99 | AI15: ='Auswertung IgG 4'!W15 -> 0
H16: 1 | I16: links infraorbital | J16: 3.6 | K16: 3.2 | L16: 2.5 | M16: 1.7 | N16: =(L16*M16) -> 4.25 | P16: 3.2 | Q16: 2.3 | R16: 2 | S16: 3 | T16: =(R16*S16) -> 6 | V16: 0 | W16: 0 | X16: 0 | Y16: 0 | Z16: 0 | AB16: 2.4 | AC16: 2 | AD16: 1.8 | AE16: 2.8 | AF16: =(AD16*AE16) -> 5.04 | AI16: ='Auswertung IgG 4'!W16 -> 0
H17: 1 | I17: A. iliaca communis links | J17: 3.9 | K17: 3.2 | L17: 2.9 | M17: 1.4 | N17: =(L17*M17) -> 4.06 | P17: 5.1 | Q17: 3.3 | R17: 3.1 | S17: 1.9 | T17: =(R17*S17) -> 5.89 | V17: 0 | W17: 0 | X17: 0 | Y17: 0 | Z17: 0 | AB17: 2.3 | AC17: 1.7 | AD17: 1.6 | AE17: 1 | AF17: =(AD17*AE17) -> 1.6 | AI17: ='Auswertung IgG 4'!W17 -> 0
H18: 1 | I18: Rechte Niere | J18: 6.2 | K18: 5 | L18: 4.2 | M18: 3.9 | N18: =(L18*M18) -> 16.38 | P18: 6.9 | Q18: 6.6 | R18: 4.2 | S18: 22.8 | T18: =(R18*S18) -> 95.76 | V18: 0 | W18: 0 | X18: 0 | Y18: 0 | Z18: 0 | AB18: 2.4 | AC18: 1.8 | AD18: 1.7 | AE18: 4.2 | AF18: =(AD18*AE18) -> 7.14 | AI18: ='Auswertung IgG 4'!W18 -> 0
H19: 1 | I19: Linke Niere | J19: 6.3 | K19: 5.1 | L19: 4.1 | M19: 4.6 | N19: =(L19*M19) -> 18.86 | P19: 10.4 | Q19: 8.1 | R19: 6.4 | S19: 4.8 | T19: =(R19*S19) -> 30.72 | V19: 0 | W19: 0 | X19: 0 | Y19: 0 | Z19: 0 | AB19: 2.5 | AC19: 1.9 | AD19: 1.8 | AE19: 2.8 | AF19: =(AD19*AE19) -> 5.04 | AI19: ='Auswertung IgG 4'!W19 -> 0
AI20: ='Auswertung IgG 4'!W20 -> 0
A21: 4 | B21: Meier, Roland | C21: 21872 | D21: 43528 | E21: 43759 | F21: 43531 | G21: 43760 | H21: 1 | I21: retroperitoneal | J21: 3.9 | K21: 3.2 | L21: 2.6 | M21: 3.6 | N21: =(L21*M21) -> 9.36 | P21: 8.9 | Q21: 5.6 | R21: 5.1 | S21: 2.7 | T21: =(R21*S21) -> 13.77 | V21: 0 | W21: 0 | X21: 0 | Y21: 0 | Z21: 0 | AB21: 0 | AC21: 0 | AD21: 0 | AE21: 0 | AF21: 0 | AI21: ='Auswertung IgG 4'!W21 -> 9.8888889 | AK21: 2.6
AI22: ='Auswertung IgG 4'!W22 -> 0
A23: 5 | B23: Zipfel, Josef | C23: 20420 | D23: 43647 | F23: 43648 | H23: 1 | I23: links infraorbital | J23: 3.6 | K23: 3.2 | L23: 2.5 | M23: 1.7 | N23: =(L23*M23) -> 4.25 | P23: 3.2 | Q23: 2.3 | R23: 2 | S23: 3 | T23: =(R23*S23) -> 6 | V23: 0 | W23: 0 | X23: 0 | Y23: 0 | Z23: 0 | AB23: 1.6 | AC23: 1.4 | AD23: 1.2 | AE23: 2.4 | AF23: =(AD23*AE23) -> 2.88 | AI23: ='Auswertung IgG 4'!W23 -> 4.9444444 | AK23: 2
H24: 1 | I24: Parotis rechts | J24: 3.6 | K24: 2.8 | L24: 2.6 | M24: 2 | N24: =(L24*M24) -> 5.2 | P24: 5.7 | Q24: 3.6 | R24: 3.4 | S24: 1.7 | T24: =(R24*S24) -> 5.78 | V24: 0 | W24: 0 | X24: 0 | Y24: 0 | Z24: 0 | AB24: 2.9 | AC24: 2.3 | AD24: 1.6 | AE24: 1.6 | AF24: =(AD24*AE24) -> 2.56 | AI24: ='Auswertung IgG 4'!W24 -> 0
AI25: ='Auswertung IgG 4'!W25 -> 0
A26: 6 | B26: Janosch, Vera | C26: 21725 | D26: 43521 | E26: 43773 | F26: 43518 | G26: 43774 | H26: 1 | I26: Intraorbital links | J26: 10.8 | K26: 9.7 | L26: 5.9 | M26: 6.9 | N26: =(L26*M26) -> 40.71 | P26: 9.5 | Q26: 5.6 | R26: 4.9 | S26: 4.4 | T26: =(R26*S26) -> 21.56 | V26: 12.7 | W26: 10.3 | X26: 7.4 | Y26: 6.2 | Z26: =(X26*Y26) -> 45.88 | AB26: 7.3 | AC26: 4.7 | AD26: 4.3 | AE26: 6.4 | AF26: =(AD26*AE26) -> 27.52 | AI26: ='Auswertung IgG 4'!W26 -> 6.4230769 | AK26: 3.2745098
H27: 1 | I27: Gl. Submandibularis links | J27: 3.2 | K27: 2.7 | L27: 2.2 | M27: 3.6 | N27: =(L27*M27) -> 7.92 | P27: 9.4 | Q27: 7.4 | R27: 5.6 | S27: 9.3 | T27: =(R27*S27) -> 52.08 | V27: 0 | W27: 0 | X27: 0 | Y27: 0 | Z27: 0 | AB27: 3.1 | AC27: 2.6 | AD27: 1.9 | AE27: 4.2 | AF27: =(AD27*AE27) -> 7.98 | AH27: Mittelwert | AI27: ='Auswertung IgG 4'!W27 -> 8.4661572 | AK27: 3.2261941
H28: 1 | I28: Gl. Submandibularis rechts | J28: 2.7 | K28: 2.3 | L28: 2.1 | M28: 3 | N28: =(L28*M28) -> 6.3 | P28: 9.1 | Q28: 7 | R28: 5.6 | S28: 8 | T28: =(R28*S28) -> 44.8 | V28: 0 | W28: 0 | X28: 0 | Y28: 0 | Z28: 0 | AB28: 3.7 | AC28: 2.9 | AD28: 2.2 | AE28: 5.4 | AF28: =(AD28*AE28) -> 11.88 | AH28: Standardabweichung | AI28: ='Auswertung IgG 4'!W28 -> 2.2861534 | AK28: 0.92753437
H29: 1 | I29: Pankreas | J29: nd | K29: nd | L29: nd | M29: nd | N29: nd | P29: 5.4 | Q29: 4 | R29: 2.8 | S29: 26.7 | T29: =(R29*S29) -> 74.76 | V29: nd | W29: nd | X29: nd | Y29: nd | Z29: nd | AB29: 2.4 | AC29: 1.5 | AD29: 1.2 | AE29: 14.4 | AF29: =(AD29*AE29) -> 17.28
A31: 7 | B31: Hos, Mete | C31: 26816 | D31: 43493 | E31: 43689 | F31: 43490 | G31: 43690 | H31: 1 | I31: links zervikal | J31: 11.8 | K31: 7.6 | L31: 7.6 | M31: 0.8 | N31: 6.1 | P31: 0 | Q31: 0 | R31: 0 | S31: 0 | T31: 0 | V31: 8.5 | W31: 5.2 | X31: 4.8 | Y31: 2.3 | Z31: 11.1 | AB31: 0 | AC31: 0 | AD31: 0 | AE31: 0 | AF31: 0
H32: 1 | I32: links zervikal | J32: 4.1 | K32: 3.2 | L32: 2.6 | M32: 2.1 | N32: 5.5 | P32: 0 | Q32: 0 | R32: 0 | S32: 0 | T32: 0 | V32: 3.8 | W32: 2.9 | X32: 2.4 | Y32: 4.2 | Z32: 10.2 | AB32: 0 | AC32: 0 | AD32: 0 | AE32: 0 | AF32: 0

Sheet SpA
B3: Name | C3: Geburtsdatum | D3: Scandatum | E3: Indikation | F3: Datum 2. FAPI PET/CT
B6: Cetin,Hatice | C6: 29594 | D6: 44946 | E6: Axiale Spondylarthropathie
B7: Öztürk,Yilmaz | C7: 37403 | D7: 44988 | E7: SpA
B8: Mahrle,Thomas | C8: 29824 | D8: 45005 | E8: SpA
B9: Navalon Olmos, Carolina | C9: 29869 | D9: 45009 | E9: SpA
B10: Märtl, Susanne | C10: 29430 | D10: 45079 | E10: SpA
B11: Arnold-Schmidt,Christine | C11: 24666 | D11: 45138 | E11: SpA
B12: Simotas,Ioannis | C12: 26106 | D12: 45152 | E12: SpA
B13: Ustinow, Oleg | C13: 23330 | D13: 45161 | E13: SpA
B14: Reichel,Claudia | C14: 24055 | D14: 45163 | E14: SpA
B15: Hübner, Claudia | C15: 25671 | D15: 45187 | E15: SpA
B16: Zenk,Manfred | C16: 22092 | D16: 45201 | E16: SpA
B17: Weber, Jürgen | C17: 24279 | D17: 45205 | E17: SpA
... B29: Rieger,Sabine | C29: 31477 | D29: 45625 | E29: SpA

Sheet PsA
B6: Name | C6: Geburtsdatum | D6: Scandatum | E6: Indikation | F6: Datum 2. FAPI PET/CT
B8: Lassel, Adriana-Codruta | C8: 29513 | D8: 44907 | E8: PsA
B9: Dölfel,Erwin | C9: 22310 | D9: 44935 | E9: PsA
B10: Ansari,Assad | C10: 32326 | D10: 44939 | E10: PsA
B11: Meister,Petra | C11: 22474 | D11: 44946 | E11: PsA
B12: Krieger,Olga | C12: 27316 | D12: 44953 | E12: PSA | F12: 45247
B13: Schad, Matthias | C13: 19835 | D13: 44956 | E13: PSA
B14: Walter,Julia | C14: 30475 | D14: 44960 | E14: PSA
B15: Pruy-Popp,Carolin | C15: 29400 | D15: 45005 | E15: PsA
B16: Marktgraf, Miriam | C16: 35020 | D16: 45016 | E16: PsA
B17: Cibura,Rajmund | C17: 25234 | D17: 45016 | E17: PsA
B18: Herzfeld, Claudia | C18: 29146 | D18: 45033 | E18: PsA
B19: Gnanapiragasam,Edna | C19: 31202 | D19: 45051 | E19: PSA
B20: Frisch,Andreas | C20: 30319 | D20: 45089 | E20: PSA
B21: Peker,Fethi | C21: 22753 | D21: 45089 | E21: PSA
B22: Raithel,Benjamin | C22: 30430 | D22: 45105 | E22: PSA
B23: Braun, Harald | C23: 25904 | D23: 45110 | E23: PSA
B24: Rödig, Rosaria | C24: 20413 | D24: 45117 | E24: PSA
... B48: Drobnjak,Alexander | C48: 32392 | D48: 45464 | E48: PsA
B49: Pinkert, Wilhelm | C49: 15.15.1952 | D49: 45506 | E49: PsA
B50: Ramic,Ramo | C50: 29066 | D50: 45509 | E50: PsA
B51: Evers, Anke | C51: 25391 | D51: 45520 | E51: PsA
B52: Dolhaniuk, Ursuala | C52: 23516 | D52: 45544 | E52: PsA
B53: Mercan, Sinan | C53: 33772 | D53: 45583 | E53: PsA
B54: Strobel, Marion | C54: 23093 | D54: 45642 | E54: PsA
B55: Haber,Betina | C55: 21804 | D55: 45674 | E55: PsA

Sheet Rheumatoide Arthritis
B1: Name | C1: Geburtsdatum | D1: Scandatum | E1: Indikation | F1: Datum 2. FAPI PET/CT | G1: Datum 3. FAPI PET/CT | H1: Datum 4. FAPI PET/CT
B4: Volkamer, Erich | C4: 21824 | D4: 44949 | E4: RA
B5: Zipfel,Bernd | C5: 24835 | D5: 45033 | E5: RA | F5: 45114
B6: Seitz, Rita | C6: 23862 | D6: 45082 | E6: RA mit pulmonaler Beteiligung
B7: Canovic, Alma | C7: 26218 | D7: 45103 | E7: RA
B8: Bernabei,Vanessa | C8: 33325 | D8: 45117 | E8: RA
B9: Weller,Günter | C9: 23728 | D9: 45128 | E9: RA
B10: Bauer, Katrin | C10: 25098 | D10: 45145 | E10: RA mit pulmonaler Beteiligung
B11: Zehnter,Petra | C11: 23681 | D11: 45145 | E11: RA
B12: Wilhelm,Michael | C12: 24133 | D12: 45149 | E12: Seronegative RA | F12: 45457
B13: Morner, Jürgen | C13: 22912 | D13: 45159 | E13: RA
B14: Sichart,Güner | C14: 24881 | D14: 45173 | E14: RA | F14: 45341
B15: Schatt,Stefanie | C15: 27348 | D15: 45096 | E15: RA | F15: 45201
B16: Petrzik, Kerstin | C16: 24896 | D16: 45208 | E16: RA und Mukoviszidose
B17: Dietrich,Monika | C17: 21480 | D17: 45215 | E17: RA
B18: Wölfel,Sonja | C18: 22586 | D18: 45212 | E18: RA | F18: 45600
B19: Isenberg,Catherine Jill | C19: 29291 | D19: 45222 | E19: RA
B20: Gensler,Katrin | C20: 27033 | D20: 45223 | E20: RA/periphere SpA
B21: Oppelt, Erika | C21: 23335 | D21: 45233 | E21: RA
B22: Thäter,Norbert | C22: 20932 | D22: 45247 | E22: RA DD:PsA
B23: Franz,Ludwig | C23: 23035 | D23: 45142 | E23: RA
B24: Rauh,claudia | C24: 28286 | D24: 45313 | E24: RA, Multi Drug Resistance | F24: 45429
B25: Bude-Klemmer, Judith | C25: 23923 | D25: 45331 | E25: RA, Multi Drug Resistance
B26: Link, Theodor | C26: 22664 | D26: 45373 | E26: RA
B27: Böhm,Diethard | C27: 23920 | D27: 45418 | E27: Rheumatoide Arthritis
B28: Bruder,Sylvia | C28: 25155 | D28: 45460 | E28: RA
B29: Behr,Marion | C29: 27517 | D29: 45471 | E29: RA
B30: Grüner, Manfred | C30: 22049 | D30: 45481 | E30: RA
B31: Lorenz,Armin | C31: 20256 | D31: 45499 | E31: RA
B32: Liegl,Wilhelm | C32: 22785 | D32: 45555 | E32: RA
B33: Spadafora Bauer, Marirosa | C33: 24419 | D33: 45569 | E33: Therapierefraktäre RA
B34: Liebig, Birgit | C34: 24545 | D34: 45583 | E34: RA
B35: Gleißner, Matthias | C35: 25773 | D35: 45607 | E35: Rheumatoide Arthritis
B36: Gruna, Boguslawa | C36: 22224 | D36: 45642 | E36: RA

Sheet Dynamische Messungen
A1: Dynamische Messungen
B5: Name | D5: Geburtsdatum | F5: Scandatum | H5: Indikation
B8: Öztürk,Yilmaz | D8: 37403 | F8: 44988 | H8: SpA

Sheet DEGINF
B1: Name | C1: Geburtsdatum | D1: Scandatum | E1: Indikation | F1: INF | G1: DEG | H1: SUV max | I1: SUV mean | J1: MAV | K1: TL-FAPI | L1: Lokalisation | M1: DEG gesamt | N1: INF gesamt | P1: MRT 0=nein 1= ja | Q1: Region 1=Hand, 2= Fuß, 3= Wirbelsäule, 4= Schulter, 5= Knie, 6= Ellenbogen | R1: Datum
A2: 1 | B2: Tyrach, Beate | C2: 23328 | D2: 43416 | E2: PSA | F2: 1 | G2: 0 | H2: 3.3 | I2: 2.2 | J2: 2.1 | K2: =(I2*J2) -> 4.62 | L2: LWK 3
F4: 0 | G4: 1 | H4: 1.1 | I4: 0.6 | J4: 2.1 | K4: =(I4*J4) -> 1.26 | L4: MTP 4 links
F5: 0 | G5: 1 | H5: 2.1 | I5: 0.9 | J5: 1.8 | K5: =(I5*J5) -> 1.62 | L5: Hallux rechts
F6: 0 | G6: 1 | H6: 1.8 | I6: 1.1 | J6: 1 | K6: =(I6*J6) -> 1.1 | L6: AC-Gelenk links
F7: 0 | G7: 1 | H7: 1.7 | I7: 1 | J7: 1 | K7: =(I7*J7) -> 1 | L7: AC-Gelenk rechts
F8: 0 | G8: 1 | H8: 1.6 | I8: 1.4 | J8: 0.8 | K8: =(I8*J8) -> 1.12 | L8: SC-Gelenk links | M8: 1 | N8: 1 | P8: 1 | Q8: 3 | R8: 43294
A10: 2 | B10: Behne, Maik | C10: 30062 | D10: 43423 | E10: SPA | F10: 1 | G10: 0 | H10: 4.8 | I10: 2.8 | J10: 1.8 | K10: =(I10*J10) -> 5.04 | L10: HW4 li FG
F11: 1 | G11: 0 | H11: 4.5 | I11: 2.6 | J11: 3 | K11: =(I11*J11) -> 7.8 | L11: HWK 8 Proc. Spinosus
F12: 1 | G12: 0 | H12: 3.7 | I12: 2.5 | J12: 1.7 | K12: =(I12*J12) -> 4.25 | L12: HWK5 art. Costotransversalis
F13: 1 | G13: 0 | H13: 4.9 | I13: 2.7 | J13: 1.5 | K13: =(I13*J13) -> 4.05 | L13: BWK 8 Art. Costotransversale
F14: 1 | G14: 0 | H14: 4.9 | I14: 3 | J14: 1.2 | K14: =(I14*J14) -> 3.6 | L14: BWK 10 Art. Costotransversale
F15: 1 | G15: 0 | H15: 3.9 | I15: 2.5 | J15: 2.9 | K15: =(I15*J15) -> 7.25 | L15: LWK 5 FG
F16: 1 | G16: 0 | H16: 4.6 | I16: 2.1 | J16: 3.6 | K16: =(I16*J16) -> 7.56 | L16: ISG links
F17: 1 | G17: 0 | H17: 6.2 | I17: 3.7 | J17: 1.3 | K17: =(I17*J17) -> 4.81 | L17: Flexoren Oberschenkel links
F18: 1 | G18: 0 | H18: 5.4 | I18: 3 | J18: 5.8 | K18: =(I18*J18) -> 17.4 | L18: Flexoren Kniegelenk
F19: 1 | G19: 0 | H19: 5.1 | I19: 3.1 | J19: 2.2 | K19: =(I19*J19) -> 6.82 | L19: Flexoren Kniegelenk
F20: 1 | G20: 0 | H20: 5.2 | I20: 3.1 | J20: 1.6 | K20: =(I20*J20) -> 4.96 | L20: Flexoren Kniegelenk
F21: 1 | G21: 0 | H21: 4.1 | I21: 2.2 | J21: 2.1 | K21: =(I21*J21) -> 4.62 | L21: Peronaeus Sehne rechts
F22: 1 | G22: 0 | H22: 8.2 | I22: 4.7 | J22: 1.4 | K22: =(I22*J22) -> 6.58 | L22: Plantarsehne Dig V rechts
... F34: 0 | G34: 1 | H34: 2.7 | I34: 2.1 | J34: 1.3 | K34: =(I34*J34) -> 2.73 | L34: Daumensattelgelenk rechts
F35: 0 | G35: 1 | H35: 3.6 | I35: 2.1 | J35: 2.3 | K35: =(I35*J35) -> 4.83 | L35: rechts patellär | M35: 1 | N35: 1 | P35: 1 | Q35: 1,2,3 | R35: 43375
A37: 3 | B37: Pachur, Christina | C37: 27932 | D37: 43423 | E37: RA | F37: 1 | G37: 0 | H37: 6.5 | I37: 3.8 | J37: 1.6 | K37: =(I37*J37) -> 6.08 | L37: BWK 11
F38: 1 | G38: 0 | H38: 5.6 | I38: 3.2 | J38: 1.7 | K38: =(I38*J38) -> 5.44 | L38: Flexoren Oberschenkel
F39: 1 | G39: 0 | H39: 12.9 | I39: 7.7 | J39: 2.6 | K39: =(I39*J39) -> 20.02 | L39: Extensoren Sprunggelenk rechts
F40: 1 | G40: 0 | H40: 6.2 | I40: 3.6 | J40: 2.4 | K40: =(I40*J40) -> 8.64 | L40: Extensoren Hallux rechts
F41: 1 | G41: 0 | H41: 11.7 | I41: 7.1 | J41: 1 | K41: =(I41*J41) -> 7.1 | L41: Extensor poll brevis links
F42: 1 | G42: 0 | H42: 4.3 | I42: 3.5 | J42: 1.2 | K42: =(I42*J42) -> 4.2 | L42: DIP 2 links
F44: 0 | G44: 1 | H44: 2.7 | I44: 1.7 | J44: 1.1 | K44: =(I44*J44) -> 1.87 | L44: AC-Gelenk rechts
F45: 0 | G45: 1 | H45: 2.6 | I45: 1.8 | J45: 1.3 | K45: =(I45*J45) -> 2.34 | L45: AC-Gelenk links | M45: 1 | N45: 1 | P45: 1 | Q45: 1 | R45: 43410
A47: 4 | B47: Heckman, Clifton | C47: 24418 | D47: 43430 | E47: SPA | F47: 1 | G47: 0 | H47: 5 | I47: 2.9 | J47: 4.9 | K47: =(I47*J47) -> 14.21 | L47: HWK2/3 links
F48: 1 | G48: 0 | H48: 5.3 | I48: 3.3 | J48: 1.8 | K48: =(I48*J48) -> 5.94 | L48: Costoclavikulargelenk re
F49: 1 | G49: 0 | H49: 3.6 | I49: 2.5 | J49: 1.3 | K49: =(I49*J49) -> 3.25 | L49: Costotransversalgelenk
F50: 1 | G50: 0 | H50: 5.2 | I50: 2.9 | J50: 1.7 | K50: =(I50*J50) -> 4.93 | L50: Costotransversalgelenk BWK 11 re
F51: 1 | G51: 0 | H51: 4.6 | I51: 2.9 | J51: 1.6 | K51: =(I51*J51) -> 4.64 | L51: Costotransversalgelenk BWK 11 li
F52: 1 | G52: 0 | H52: 4.8 | I52: 3.9 | J52: 1 | K52: =(I52*J52) -> 3.9 | L52: LWK 4 re
F53: 1 | G53: 0 | H53: 3.9 | I53: 2.7 | J53: 1.5 | K53: =(I53*J53) -> 4.05 | L53: LWK 2
F54: 1 | G54: 0 | H54: 3.8 | I54: 2.8 | J54: 1.4 | K54: =(I54*J54) -> 3.92 | L54: Proc. Spinosus 5
F55: 1 | G55: 0 | H55: 3.2 | I55: 2.1 | J55: 1.4 | K55: =(I55*J55) -> 2.94 | L55: ISG links
F57: 0 | G57: 1 | H57: 2.4 | I57: 2.4 | J57: 0.8 | K57: =(I57*J57) -> 1.92 | L57: Hallux rechts | M57: 1 | N57: 1 | P57: 1 | Q57: 3 | R57: 43397
...

Sheet Follow-up DEGINF
B1: Name | C1: Geburtsdatum | D1: Scandatum | E1: Indikation | F1: INF | G1: DEG | H1: SUV max | I1: SUV mean | J1: MAV | K1: TL-FAPI | L1: Lokalisation | M1: DEG gesamt | N1: INF gesamt | Q1: Therapiemedikament | T1: MRT 0=nein 1= ja | U1: Region 1=Hand, 2= Fuß, 3= Wirbelsäule | V1: Datum
A2: 1 | B2: Heckman, Clifton | C2: 24418 | D2: 43430 | E2: SpA | F2: 1 | G2: 0 | H2: 5 | I2: 2.9 | J2: 4.9 | K2: =(I2*J2) -> 14.21 | L2: HWK2/3 links
F3: 1 | G3: 0 | H3: 5.3 | I3: 3.3 | J3: 1.8 | K3: =(I3*J3) -> 5.94 | L3: Costoclavikulargelenk re
F4: 1 | G4: 0 | H4: 3.6 | I4: 2.5 | J4: 1.3 | K4: =(I4*J4) -> 3.25 | L4: Costotransversalgelenk
F5: 1 | G5: 0 | H5: 5.2 | I5: 2.9 | J5: 1.7 | K5: =(I5*J5) -> 4.93 | L5: Costotransversalgelenk BWK 11 re
F6: 1 | G6: 0 | H6: 4.6 | I6: 2.9 | J6: 1.6 | K6: =(I6*J6) -> 4.64 | L6: Costotransversalgelenk BWK 11 li
F7: 1 | G7: 0 | H7: 4.8 | I7: 3.9 | J7: 1 | K7: =(I7*J7) -> 3.9 | L7: LWK 4 re
F8: 1 | G8: 0 | H8: 3.9 | I8: 2.7 | J8: 1.5 | K8: =(I8*J8) -> 4.05 | L8: LWK 2
F9: 1 | G9: 0 | H9: 3.8 | I9: 2.8 | J9: 1.4 | K9: =(I9*J9) -> 3.92 | L9: Proc. Spinosus 5
F10: 1 | G10: 0 | H10: 3.2 | I10: 2.1 | J10: 1.4 | K10: =(I10*J10) -> 2.94 | L10: ISG links
F11: 0 | G11: 1 | H11: 2.4 | I11: 2.4 | J11: 0.3 | K11: =(I11*J11) -> 0.72 | L11: Hallux rechts | M11: 1 | N11: 1 | T11: 1 | U11: 3 | V11: 43397
D15: 43654 | F15: 1 | G15: 0 | H15: 0 | I15: 0 | J15: 0 | K15: =(I15*J15) -> 0 | L15: HWK2/3 links
F16: 1 | G16: 0 | H16: 5.4 | I16: 3.2 | J16: 1.8 | K16: =(I16*J16) -> 5.76 | L16: Costoclavikulargelenk re
F17: 1 | G17: 0 | H17: 0 | I17: 0 | J17: 0 | K17: =(I17*J17) -> 0 | L17: Costotransversalgelenk
F18: 1 | G18: 0 | H18: 0 | I18: 0 | J18: 0 | K18: =(I18*J18) -> 0 | L18: Costotransversalgelenk BWK 11 re
F19: 1 | G19: 0 | H19: 0 | I19: 0 | J19: 0 | K19: =(I19*J19) -> 0 | L19: Costotransversalgelenk BWK 11 li
F20: 1 | G20: 0 | H20: 0 | I20: 0 | J20: 0 | K20: =(I20*J20) -> 0 | L20: LWK 4 re
F21: 1 | G21: 0 | H21: 3.2 | I21: 1.9 | J21: 0.8 | K21: =(I21*J21) -> 1.52 | L21: LWK 2
F22: 1 | G22: 0 | H22: 4.5 | I22: 2.7 | J22: 1.9 | K22: =(I22*J22) -> 5.13 | L22: Proc. Spinosus 5
F23: 1 | G23: 0 | H23: 5.6 | I23: 3.4 | J23: 3.2 | K23: =(I23*J23) -> 10.88 | L23: Schulter inks
F24: 1 | G24: 0 | H24: 0 | I24: 0 | J24: 0 | K24: =(I24*J24) -> 0 | L24: ISG links
F25: 0 | G25: 1 | H25: 2.5 | I25: 1.9 | J25: 0.4 | K25: =(I25*J25) -> 0.76 | L25: Hallux rechts | M25: 1 | N25: 1 | P25: Zunehmende Läsion Proc. Spinosus LWK 5 neue Läsion Schulter links
A27: 2 | B27: Pfister, Alois | C27: 23438 | D27: 43374 | E27: RA | F27: 1 | G27: 0 | H27: 4.8 | I27: 2 | J27: 17.7 | K27: =(I27*J27) -> 35.4 | L27: Schultergelenk li
F28: 1 | G28: 0 | H28: 13.9 | I28: 7.2 | J28: 14.4 | K28: =(I28*J28) -> 103.68 | L28: Kniegelenk re
F29: 1 | G29: 0 | H29: 10.2 | I29: 6 | J29: 0.9 | K29: =(I29*J29) -> 5.4 | L29: Art. Tibiofibularis li
F30: 1 | G30: 0 | H30: 10 | I30: 5.3 | J30: 3 | K30: =(I30*J30) -> 15.9 | L30: OSG li
F31: 1 | G31: 0 | H31: 10 | I31: 5 | J31: 3.9 | K31: =(I31*J31) -> 19.5 | L31: USG li
F32: 1 | G32: 0 | H32: 8.8 | I32: 5.8 | J32: 2.1 | K32: =(I32*J32) -> 12.18 | L32: Achillessehne re
F33: 1 | G33: 0 | H33: 10.2 | I33: 6 | J33: 2.3 | K33: =(I33*J33) -> 13.8 | L33: Großzehenendgelenk re
F34: 1 | G34: 0 | H34: 6.1 | I34: 3.6 | J34: 5.7 | K34: =(I34*J34) -> 20.52 | L34: links carpal
F35: 1 | G35: 0 | H35: 8.4 | I35: 4.7 | J35: 3.1 | K35: =(I35*J35) -> 14.57 | L35: rechts ulnocarpal
F36: 1 | G36: 0 | H36: 7.7 | I36: 4.4 | J36: 1.7 | K36: =(I36*J36) -> 7.48 | L36: rechts radiocarpal
F37: 1 | G37: 0 | H37: 4.1 | I37: 2.5 | J37: 1.1 | K37: =(I37*J37) -> 2.75 | L37: 4. Zehe re
F39: 0 | G39: 1 | H39: 3.2 | I39: 2.2 | J39: 0.7 | K39: =(I39*J39) -> 1.54 | L39: links patellär | M39: 1 | N39: 1
F41: 1 | G41: 0 | H41: 0 | I41: 0 | J41: 0 | K41: =(I41*J41) -> 0 | L41: Schultergelenk li
F42: 1 | G42: 0 | H42: 4 | I42: 1.9 | J42: 21.8 | K42: =(I42*J42) -> 41.42 | L42: Kniegelenk re
F43: 1 | G43: 0 | H43: 0 | I43: 0 | J43: 0 | K43: =(I43*J43) -> 0 | L43: Art. Tibiofibularis li
F44: 1 | G44: 0 | H44: 0 | I44: 0 | J44: 0 | K44: =(I44*J44) -> 0 | L44: OSG li
F45: 1 | G45: 0 | H45: 0 | I45: 0 | J45: 0 | K45: =(I45*J45) -> 0 | L45: USG li
F46: 1 | G46: 0 | H46: 0 | I46: 0 | J46: 0 | K46: =(I46*J46) -> 0 | L46: Achillessehne re
...

Sheet FAPI-MRT
B1: Name | C1: Geburtsdatum | D1: Scandatum | E1: Indikation | F1: Region 1=Hand, 2= Fuß, 3= Wirbelsäule, 4= Schulter, 5= Knie, 6= Ellenbogen | G1: Datum
A2: 1 | B2: Tyrach, Beate | C2: 23328 | D2: 43416 | E2: PSA | F2: 3 | G2: 43294
A3: 2 | B3: Behne, Maik | C3: 30062 | D3: 43423 | E3: SPA | F3: 1,2,3 | G3: 43375
A4: 3 | B4: Pachur, Christina | C4: 27932 | D4: 43423 | E4: RA | F4: 1 | G4: 43410
A5: 4 | B5: Heckman, Clifton | C5: 24418 | D5: 43430 | E5: SPA | F5: 3 | G5: 43397
A6: 5 | B6: Oeser, Heidi | C6: 21589 | D6: 43444 | E6: SPA | F6: 3 | G6: 43424
A7: 6 | B7: Sindel, Friedrich | C7: 18099 | D7: 43472 | E7: RA | F7: 4 | G7: 43343
A8: 7 | B8: Popp-Kinzel, Erika | C8: 20776 | D8: 43479 | E8: Psoriasisarthritis | F8: 2 | G8: 43417
A9: 8 | B9: Stieb-Sackmann, Susanne | C9: 24023 | D9: 43493 | E9: Spondylarthropathie | F9: 2 | G9: 43479
A10: 9 | B10: Seuss, Gerlinde | C10: 23985 | D10: 43514 | E10: Rheumatoide Arthritis | F10: 3.4 | G10: 43347
A11: 10 | B11: Strahl, Petra | C11: 24436 | D11: 43521 | E11: Psoriasisarthritis | F11: 3 | G11: 43467
A12: 11 | B12: Hemman, Christiane | C12: 21899 | D12: 43521 | E12: Spondylarthropathie | F12: 1 | G12: 43755
A13: 12 | B13: Hirt, Renate | C13: 22404 | D13: 43549 | E13: Psoriasisarthritis | F13: 1 | G13: 43521
A14: 13 | B14: Blädel, Thorsten | C14: 27215 | D14: 43556 | E14: Spondylarthropathie | F14: 5 | G14: 43683
A15: 14 | B15: Pehlivan, Selda | C15: 26463 | D15: 43605 | E15: Psoriasisarthritis | F15: 3.5 | G15: 43605
... A20: 19 | B20: Sperl, Dan | C20: 25089 | D20: 43787 | E20: Spondylarthropathie | F20: 3 | G20: 43768
A21: 20 | B21: Saglibene, Loreto | C21: 21542 | D21: 43794 | E21: Psoriasisarthritis | F21: 1,3,4 | G21: 43818
A22: 21 | B22: Zink, Verena | C22: 30985 | D22: 43801 | E22: SpA | F22: 3 | G22: 43745
A23: 22 | B23: Günes, Serdar | C23: 30008 | D23: 43808 | E23: SpA | F23: 3 | G23: 44242
A24: 23 | B24: Lieke, Sandra | C24: 25193 | D24: 43815 | E24: pre-RA | F24: 1 | G24: 43719
A25: 24 | B25: Dinc, Arfe | C25: 23228 | D25: 43815 | E25: SpA | F25: 3 | G25: 43600
A26: 25 | B26: Conrad, Christian | C26: 22284 | D26: 43850 | E26: SpA | F26: 3 | G26: 43929
A27: 26 | B27: Raducu, Nicolae-Mihai | C27: 28212 | D27: 43854 | E27: SpA | F27: 3 | G27: 43815
A28: 27 | B28: Witkovsky, Cornelia | C28: 24547 | D28: 43854 | E28: Psoriasisarthritis | F28: 1 | G28: 43753
A29: 28 | B29: Anderson, Kristina | C29: 32258 | D29: 43857 | E29: SpA | F29: 1.3 | G29: 43699
A30: 29 | B30: Geyer, Achim | C30: 25439 | D30: 44088 | E30: Psoriasisarthritis | F30: 1 | G30: 44180
A31: 30 | B31: Daxenberger, Raphael | C31: 32194 | D31: 44092 | E31: SpA | F31: 1.3 | G31: 44004
A32: 31 | B32: Ruck, Wolfgang | C32: 24911 | D32: 44099 | E32: Prä-RA | F32: 1 | G32: 43998
A33: 32 | B33: Stöcklein,Tanja | C33: 28273 | D33: 44008 | E33: Prä-RA | F33: 2 | G33: 43843
... A48: 47 | B48: Gries, Ute | C48: 25500 | D48: 43927 | E48: SpA | F48: 4 | G48: 43986
A49: 48 | B49: Kittel,Karsten | C49: 30.02.1966 | D49: 43924 | E49: Rheumatoide Arthritis | F49: 3 | G49: 44094
A50: 49 | B50: Lustig, Drazen | C50: 26577 | D50: 43924 | E50: SpA | F50: 3 | G50: 43866
A51: 50 | B51: Rössle,Stefan | C51: 30246 | D51: 43924 | E51: SpA | F51: 1.3 | G51: 43928
A52: 51 | B52: Pabst,Rudolf | C52: 22028 | D52: 43906 | E52: Psoriasis Arthritis | F52: 1 | G52: 43895
A53: 52 | B53: Moßburger, Sandra | C53: 29676 | D53: 43903 | E53: Psoriasis Arthritis | F53: 1 | G53: 43935
A54: 53 | B54: Greif, Jürgen | C54: 21332 | D54: 44106 | E54: SpA | F54: 3 | G54: 44092
A55: 54 | B55: Söllner, Ute | C55: 22959 | D55: 44106 | E55: Rheumatoide Arthritis | F55: 1 | G55: 44084
A56: 55 | B56: Lohmann, Björn | C56: 26584 | D56: 44109 | E56: Psoriasisarthritis | F56: 6 | G56: 44148
A57: 56 | B57: Greif, Jürgen | C57: 21332 | D57: 44106 | E57: SpA | F57: 3 | G57: 44092
A58: 57 | B58: Bittner, Katja | C58: 24469 | D58: 44123 | E58: SpA | F58: 3 | G58: 44006
...

Sheet Histologie
A1: Name | B1: Geburtsdatum | C1: Scandatum 1. FAPI | D1: Indikation | E1: Datum 2. FAPI PET/CT | F1: Datum 1. FDG PET | G1: Datum 2. FDG PET | I1: Histologie im Soarian 0=nein, 1=ja | J1: Ort der Probenentnahme | K1: Datum der Probenentnahme
A2: Berisha, Astrit | B2: 31446 | C2: 43451 | D2: IgG 4-Syndrom | E2: 43717 | F2: 43551 | I2: Nein
A3: Schmitt, Emil | B3: 22492 | C3: 43479 | D3: IgG 4-Syndrom | I3: Ja | J3: Glandula sublingualis | K3: 41583
A4: Hos, Mete | B4: 26816 | C4: 43493 | D4: IgG 4-Syndrom | E4: 43689 | F4: 43490 | G4: 43690 | I4: Ja | J4: Tonsille links /Atherom link /Lymphknoten cervikal links | K4: 43392
A5: Seffert, Gerda | B5: 12290 | C5: 43507 | D5: IgG 4-Syndrom | I5: Nein
A6: Kraus, Andreas | B6: 19725 | C6: 43507 | D6: IgG 4-Syndrom | F6: 43501 | I6: Nein
A7: Lederer, Janina | B7: 33555 | C7: 43514 | D7: IgG 4-Syndrom | I7: Ja | J7: Retroperitonealer Tumor//Terminales Ileum | K7: 11.05.2018//11.12.2017
A8: Janosch, Vera | B8: 21725 | C8: 43521 | D8: IgG-4-Syndrom | F8: 43518 | I8: Ja | J8: Orbitale Raumforderung | K8: 43259
A9: Kollorz, Uwe | B9: 24925 | C9: 43605 | D9: IgG4 | F9: 43606 | I9: Ja | J9: Nierenstanzzylinder | K9: 42593
A10: Zipfel, Josef | B10: 20420 | C10: 43647 | D10: IgG4 | F10: 43648 | I10: Ja | J10: Weichgewebsprobe infraorbital links | K10: 43542
A11: Meier, Roland | B11: 21872 | C11: 43528 | D11: IgG-4-Syndrom | F11: 43531 | I11: Nein
A12: Thal, Hans-Günther | B12: 21814 | C12: 43528 | D12: IgG-4-Syndrom | F12: 43537 | I12: Nein
A13: Kohles, Cathrin | B13: 30190 | C13: 43752 | D13: IgG 4-Syndrom | I13: Nein

Sheet Auswertung IgG 4
B1: Name | C1: Geburtsdatum | D1: Datum 1. FAPI | E1: Datum 2. FAPI | F1: Datum 1. FDG | G1: Datum 2. FDG | H1: Number of lesions | I1: Location | J1: 1. FAPI SUVmax | K1: SUVpeak | L1: SUVmean | M1: MTV | N1: TLG | P1: FAPi pos CT neg. | T1: Aorta | U1: mean SUV max | W1: TBR FAPI | Y1: SUVmax pP | Z1: SUVpeak pP | AA1: SUV mean pP | AB1: MTV pP | AC1: TLG pP | AF1: wbTL-FAPI 1 | AG1: wbTL-FAPI 2 | AH1: wbTLG1 | AI1: wbTLG2 | AK1: Aorta | AL1: Muscle | AM1: Liver | AO1: 2. FAPI SUVmax | AP1: SUVpeak | AQ1: SUVmean | AR1: MTV | AS1: TLG | AT1: wbTL-FAPI 2 | AV1: Aorta | AW1: Muscle | AX1: Liver | AZ1: 1. FDG SUVmax | BA1: SUVpeak | BB1: SUVmean | BC1: MTV | BD1: TLG | BF1: Aorta | BG1: mean SUVmax | BI1: TBR FDG | BK1: SUVmax pP | BL1: SUVpeak pP | BM1: SUV mean pP | BN1: MTV pP | BO1: TLG pP | BQ1: Aorta | BR1: Muscle | BS1: Liver | BU1: 2. FDG SUVmax | BV1: SUVpeak | BW1: SUVmean | BX1: MTV | BY1: TLG | BZ1: wbTLG2 | CB1: Aorta | CC1: Muscle | CD1: Liver | CF1: Therapie | CJ1: FDG first | CK1: FDG second | CL1: FAPI first | CM1: FAPI second
A2: 1 | B2: Berisha, Astrit | C2: 31446 | D2: 43451 | E2: 43717 | F2: 43551 | G2: 43718 | H2: 1 | I2: links retroperitoneal mit Kontakt zur li Nebenniere | J2: 9.7 | K2: 6.6 | L2: 5.2 | M2: 7.4 | N2: =(L2*M2) -> 38.48 | R2: 1 | T2: 0.9 | W2: =J2/T2 -> 10.777778 | Y2: =J2 -> 9.7 | Z2: =K2 -> 6.6 | AA2: =L2 -> 5.2 | AB2: =M2 -> 7.4 | AC2: =N2 -> 38.48 | AE2: SD | AF2: 38.48 | AG2: 30.1 | AH2: 20.16 | AI2: 0 | AJ2: CR | AK2: 0.7 | AL2: 0.9 | AM2: 0.7 | AO2: 6.1 | AP2: 4.6 | AQ2: 3.5 | AR2: 8.6 | AS2: =(AQ2*AR2) -> 30.1 | AV2: 0.6 | AW2: 1.1 | AX2: 0.5 | AZ2: 8.1 | BA2: 5.7 | BB2: 4.8 | BC2: 4.2 | BD2: =(BB2*BC2) -> 20.16 | BF2: 1.7 | BI2: =(AZ2/BF2) -> 4.7647059 | BK2: 8.1 | BL2: 5.7 | BM2: 4.8 | BN2: 4.2 | BO2: =(BM2*BN2) -> 20.16 | BQ2: 1.7 | BR2: 0.5 | BS2: 2.3 | BU2: 0 | BV2: 0 | BW2: 0 | BX2: 0 | BY2: 0 | CB2: 1.6 | CC2: 0.5 | CD2: 2.3 | CF2: 2x Rituximab/Zuvor Cortison | CJ2: 272 | CK2: 281 | CL2: 141 | CM2: 152
A4: 2 | B4: Kraus, Andreas | C4: 19725 | D4: 43507 | E4: 43745 | F4: 43501 | G4: 43746 | H4: 1 | I4: Aorta abdominalis | J4: 7.1 | K4: 5.5 | L4: 3.7 | M4: 29.9 | N4: =(L4*M4) -> 110.63 | R4: 1 | T4: 0.8 | W4: =J4/T4 -> 8.875 | Y4: =J4 -> 7.1 | Z4: =K4 -> 5.5 | AA4: =L4 -> 3.7 | AB4: =M4 -> 29.9 | AC4: =N4 -> 110.63 | AE4: PR | AF4: 110.63 | AG4: 32.56 | AH4: 101.52 | AI4: 0 | AJ4: CR | AK4: 0.8 | AL4: 0.9 | AM4: 0.4 | AO4: 4.2 | AP4: 2.8 | AQ4: 2.2 | AR4: 14.8 | AS4: =(AQ4*AR4) -> 32.56 | AV4: 1.1 | AW4: 1.2 | AX4: 0.5 | AZ4: 5 | BA4: 4 | BB4: 2.7 | BC4: 37.6 | BD4: =(BB4*BC4) -> 101.52 | BF4: 1.5 | BI4: =(AZ4/BF4) -> 3.3333333 | BK4: 5 | BL4: 4 | BM4: 2.7 | BN4: 37.6 | BO4: =(BM4*BN4) -> 101.52 | BQ4: 1.5 | BR4: 0.6 | BS4: 2.2 | BU4: 0 | BV4: 0 | BW4: 0 | BX4: 0 | BY4: 0 | CB4: 1.5 | CC4: 0.6 | CD4: 2.4 | CF4: 4xRituximab | CJ4: 202 | CK4: 212 | CL4: 134 | CM4: 142
A6: 3 | B6: Kollorz, Uwe | C6: 24925 | D6: 43605 | E6: 43766 | F6: 43606 | G6: 43767 | H6: 1 | I6: Intracerebral occipital | J6: 10.3 | K6: 4.4 | L6: 6.5 | M6: 1.8 | N6: =(L6*M6) -> 11.7 | P6: 1 | R6: 14 | T6: 0.7 | U6: =AVERAGE(J6:J19) -> 6.9214286 | W6: =(U6/T6) -> 9.8877551 | Y6: =MAX(J6:J19) -> 11.9 | Z6: =AVERAGE(K6:K19) -> 4.6571429 | AA6: =AVERAGE(L6:L19) -> 4.0428571 | AB6: =AVERAGE(M6:M19) -> 10.271429 | AC6: =AVERAGE(N6:N19) -> 47.83 | AE6: PR | AF6: =SUM(N6:N19) -> 669.62 | AG6: =SUM(AS6:AS19) -> 146.33 | AH6: 425.65 | AI6: 8.1 | AJ6: PR | AK6: 0.7 | AL6: 0.8 | AM6: 0.5 | AO6: 1.8 | AP6: 1.2 | AQ6: 1.2 | AR6: 1.6 | AS6: =(AQ6*AR6) -> 1.92 | AV6: 0.7 | AW6: 0.8 | AX6: 0.5 | AZ6: 12.8 | BA6: 10.2 | BB6: 8.9 | BC6: 3.5 | BD6: =(BB6*BC6) -> 31.15 | BF6: 1.8 | BG6: =AVERAGE(AZ6:AZ19) -> 6.0923077 | BI6: =(BG6/BF6) -> 3.3846154 | BK6: =MAX(AZ6:AZ19) -> 14.4 | BL6: =AVERAGE(BA6:BA19) -> 4.5692308 | BM6: =AVERAGE(BB8:BB19) -> 3.3916667 | BN6: =AVERAGE(BC8:BC19) -> 8.85 | BO6: =AVERAGE(BD8:BD19) -> 32.875 | BQ6: 1.8 | BR6: 0.6 | BS6: 2.2 | BU6: 0 | BV6: 0 | BW6: 0 | BX6: 0 | BY6: 0 | CB6: 1.7 | CC6: 0.6 | CD6: 2.2 | CJ6: 205 | CK6: 204 | CL6: 116 | CM6: 122
H7: 1 | I7: Intracerebral rechts temporooccipital | J7: 3.3 | K7: 1.4 | L7: 2.1 | M7: 1.1 | N7: =(L7*M7) -> 2.31 | P7: 1 | AO7: 1.1 | AP7: 0.7 | AQ7: 0.7 | AR7: 0.9 | AS7: =(AQ7*AR7) -> 0.63 | BU7: nd | BV7: nd | BW7: nd | BX7: nd | BY7: nd
H8: 1 | I8: Sinus cavernosus | J8: 11.9 | K8: 7.7 | L8: 6.8 | M8: 5.9 | N8: =(L8*M8) -> 40.12 | AO8: 3.7 | AP8: 2.6 | AQ8: 2.1 | AR8: 5.9 | AS8: =(AQ8*AR8) -> 12.39 | AZ8: 14.4 | BA8: 10.3 | BB8: 8 | BC8: 8.3 | BD8: =(BB8*BC8) -> 66.4 | BU8: 0 | BV8: 0 | BW8: 0 | BX8: 0 | BY8: 0
H9: 1 | I9: Aortenbogen | J9: 11.3 | K9: 7.7 | L9: 6.3 | M9: 23.6 | N9: =(L9*M9) -> 148.68 | AO9: 4.2 | AP9: 3.1 | AQ9: 2.3 | AR9: 18 | AS9: =(AQ9*AR9) -> 41.4 | AZ9: 8.6 | BA9: 5.9 | BB9: 4.7 | BC9: 21.5 | BD9: =(BB9*BC9) -> 101.05 | BU9: 2.7 | BV9: 2.3 | BW9: 1.8 | BX9: 4.5 | BY9: =(BW9*BX9) -> 8.1
H10: 1 | I10: Aorta thoracalis | J10: 8.8 | K10: 6.4 | L10: 4.6 | M10: 49.9 | N10: =(L10*M10) -> 229.54 | AO10: 4.1 | AP10: 3 | AQ10: 2.2 | AR10: 19.1 | AS10: =(AQ10*AR10) -> 42.02 | AZ10: 7.7 | BA10: 4.8 | BB10: 3.8 | BC10: 26 | BD10: =(BB10*BC10) -> 98.8 | BU10: 0 | BV10: 0 | BW10: 0 | BX10: 0 | BY10: 0
H11: 1 | I11: Aorta abdominalis | J11: 7.6 | K11: 5 | L11: 3.9 | M11: 15.3 | N11: =(L11*M11) -> 59.67 | AO11: 3 | AP11: 2.4 | AQ11: 1.6 | AR11: 11 | AS11: =(AQ11*AR11) -> 17.6 | AZ11: 4.3 | BA11: 2.9 | BB11: 2.2 | BC11: 31 | BD11: =(BB11*BC11) -> 68.2 | BU11: 0 | BV11: 0 | BW11: 0 | BX11: 0 | BY11: 0
H12: 1 | I12: Art. Iliaca rechts | J12: 5.1 | K12: 3.2 | L12: 2.7 | M12: 4.7 | N12: =(L12*M12) -> 12.69 | AO12: 1.8 | AP12: 1.6 | AQ12: 1.5 | AR12: 2.2 | AS12: =(AQ12*AR12) -> 3.3 | AZ12: 2.9 | BA12: 2.3 | BB12: 2.1 | BC12: 2.4 | BD12: =(BB12*BC12) -> 5.04 | BU12: 0 | BV12: 0 | BW12: 0 | BX12: 0 | BY12: 0
H13: 1 | I13: Art. Iliaca links | J13: 6.8 | K13: 4.6 | L13: 3.9 | M13: 4.3 | N13: =(L13*M13) -> 16.77 | AO13: 2.5 | AP13: 2 | AQ13: 1.4 | AR13: 2.1 | AS13: =(AQ13*AR13) -> 2.94 | AZ13: 3.1 | BA13: 2.7 | BB13: 2.2 | BC13: 3.3 | BD13: =(BB13*BC13) -> 7.26 | BU13: 0 | BV13: 0 | BW13: 0 | BX13: 0 | BY13: 0
H14: 1 | I14: Art. femoralis links | J14: 2.6 | K14: 2.1 | L14: 1.9 | M14: 1.9 | N14: =(L14*M14) -> 3.61 | AO14: 1.4 | AP14: 1.2 | AQ14: 1.1 | AR14: 1.2 | AS14: =(AQ14*AR14) -> 1.32 | AZ14: 2.9 | BA14: 1.9 | BB14: 2 | BC14: 1 | BD14: =(BB14*BC14) -> 2 | BU14: 0 | BV14: 0 | BW14: 0 | BX14: 0 | BY14: 0
H15: 1 | I15: Art. femoralis rechts | J15: 3.6 | K15: 2.4 | L15: 2.2 | M15: 2.8 | N15: =(L15*M15) -> 6.16 | AO15: 2.1 | AP15: 2 | AQ15: 1.9 | AR15: 2.1 | AS15: =(AQ15*AR15) -> 3.99 | AZ15: 2.5 | BA15: 1.9 | BB15: 2 | BC15: 1.1 | BD15: =(BB15*BC15) -> 2.2 | BU15: 0 | BV15: 0 | BW15: 0 | BX15: 0 | BY15: 0
H16: 1 | I16: links infraorbital | J16: 3.2 | K16: 2.3 | L16: 2 | M16: 3 | N16: =(L16*M16) -> 6 | AO16: 2.4 | AP16: 2 | AQ16: 1.8 | AR16: 2.8 | AS16: =(AQ16*AR16) -> 5.04 | AZ16: 3.6 | BA16: 3.2 | BB16: 2.5 | BC16: 1.7 | BD16: =(BB16*BC16) -> 4.25 | BU16: 0 | BV16: 0 | BW16: 0 | BX16: 0 | BY16: 0
H17: 1 | I17: A. iliaca communis links | J17: 5.1 | K17: 3.3 | L17: 3.1 | M17: 1.9 | N17: =(L17*M17) -> 5.89 | AO17: 2.3 | AP17: 1.7 | AQ17: 1.6 | AR17: 1 | AS17: =(AQ17*AR17) -> 1.6 | AZ17: 3.9 | BA17: 3.2 | BB17: 2.9 | BC17: 1.4 | BD17: =(BB17*BC17) -> 4.06 | BU17: 0 | BV17: 0 | BW17: 0 | BX17: 0 | BY17: 0
H18: 1 | I18: Rechte Niere | J18: 6.9 | K18: 6.6 | L18: 4.2 | M18: 22.8 | N18: =(L18*M18) -> 95.76 | AO18: 2.4 | AP18: 1.8 | AQ18: 1.7 | AR18: 4.2 | AS18: =(AQ18*AR18) -> 7.14 | AZ18: 6.2 | BA18: 5 | BB18: 4.2 | BC18: 3.9 | BD18: =(BB18*BC18) -> 16.38 | BU18: 0 | BV18: 0 | BW18: 0 | BX18: 0 | BY18: 0
H19: 1 | I19: Linke Niere | J19: 10.4 | K19: 8.1 | L19: 6.4 | M19: 4.8 | N19: =(L19*M19) -> 30.72 | AO19: 2.5 | AP19: 1.9 | AQ19: 1.8 | AR19: 2.8 | AS19: =(AQ19*AR19) -> 5.04 | AZ19: 6.3 | BA19: 5.1 | BB19: 4.1 | BC19: 4.6 | BD19: =(BB19*BC19) -> 18.86 | BU19: 0 | BV19: 0 | BW19: 0 | BX19: 0 | BY19: 0
A21: 4 | B21: Meier, Roland | C21: 21872 | D21: 43528 | E21: 43759 | F21: 43531 | G21: 43760 | H21: 1 | I21: retroperitoneal | J21: 8.9 | K21: 5.6 | L21: 5.1 | M21: 2.7 | N21: =(L21*M21) -> 13.77 | R21: 1 | T21: 0.9 | W21: =J21/T21 -> 9.8888889 | Y21: =J21 -> 8.9 | Z21: =K21 -> 5.6 | AA21: =L21 -> 5.1 | AB21: =M21 -> 2.7 | AC21: =N21 -> 13.77 | AE21: CR | AF21: 13.77 | AG21: 0 | AH21: 9.4 | AI21: 0 | AJ21: CR | AK21: 0.9 | AL21: 1 | AM21: 0.4 | AO21: 0 | AP21: 0 | AQ21: 0 | AR21: 0 | AS21: 0 | AV21: 1 | AW21: 0.9 | AX21: 0.3 | AZ21: 3.9 | BA21: 3.2 | BB21: 2.6 | BC21: 3.6 | BD21: =(BB21*BC21) -> 9.36 | BF21: 1.5 | BI21: =(AZ21/BF21) -> 2.6 | BK21: 3.9 | BL21: 3.2 | BM21: 2.6 | BN21: 3.6 | BO21: =(BM21*BN21) -> 9.36 | BQ21: 1.5 | BR21: 0.6 | BS21: 2.3 | BU21: 0 | BV21: 0 | BW21: 0 | BX21: 0 | BY21: 0 | CB21: 1.7 | CC21: 0.6 | CD21: 2.5 | CF21: 2xRituximab | CJ21: 214 | CK21: 221 | CL21: 169 | CM21: 165
A23: 5 | B23: Zipfel, Josef | C23: 20420 | D23: 43647 | F23: 43648 | H23: 1 | I23: links infraorbital | J23: 3.2 | K23: 2.3 | L23: 2 | M23: 3 | N23: =(L23*M23) -> 6 | R23: 2 | T23: 0.9 | U23: =AVERAGE(J23:J24) -> 4.45 | W23: =(U23/T23) -> 4.9444444 | Y23: =MAX(J23:J24) -> 5.7 | Z23: =AVERAGE(K23:K24) -> 2.95 | AA23: =AVERAGE(L23:L24) -> 2.7 | AB23: =AVERAGE(M23:M24) -> 2.35 | AC23: =AVERAGE(N23:N24) -> 5.89 | AE23: PR | AF23: =SUM(N23:N24) -> 11.78 | AG23: =SUM(AS23:AS24) -> 5.44 | AH23: =SUM(BD23:BD24) -> 9.45 | AI23: 0 | AJ23: CR | AK23: 0.9 | AL23: 0.8 | AM23: 0.3 | AO23: 1.6 | AP23: 1.4 | AQ23: 1.2 | AR23: 2.4 | AS23: =(AQ23*AR23) -> 2.88 | AV23: 0.9 | AW23: 0.8 | AX23: 0.3 | AZ23: 3.6 | BA23: 3.2 | BB23: 2.5 | BC23: 1.7 | BD23: =(BB23*BC23) -> 4.25 | BF23: 1.8 | BG23: =AVERAGE(AZ23:AZ24) -> 3.6 | BI23: =(BG23/BF23) -> 2 | BK23: =MAX(AZ23:AZ24) -> 3.6 | BL23: =AVERAGE(BA23:BA24) -> 3 | BM23: =AVERAGE(BB23:BB24) -> 2.55 | BN23: =AVERAGE(BC23:BC24) -> 1.85 | BO23: =AVERAGE(BD23:BD24) -> 4.725 | BQ23: 1.8 | BR23: 0.5 | BS23: 2.3 | BU23: 0 | BV23: 0 | BW23: 0 | BX23: 0 | BY23: 0 | CB23: 1.8 | CC23: 0.4 | CD23: 2.2 | CJ23: 196 | CK23: 204 | CL23: 122 | CM23: 132
H24: 1 | I24: Parotis rechts | J24: 5.7 | K24: 3.6 | L24: 3.4 | M24: 1.7 | N24: =(L24*M24) -> 5.78 | P24: 1 | AO24: 2.9 | AP24: 2.3 | AQ24: 1.6 | AR24: 1.6 | AS24: =(AQ24*AR24) -> 2.56 | AZ24: 3.6 | BA24: 2.8 | BB24: 2.6 | BC24: 2 | BD24: =(BB24*BC24) -> 5.2 | BU24: 0 | BV24: 0 | BW24: 0 | BX24: 0 | BY24: 0
A26: 6 | B26: Janosch, Vera | C26: 21725 | D26: 43521 | E26: 43773 | F26: 43518 | G26: 43774 | H26: 1 | I26: Intraorbital links | J26: 9.5 | K26: 5.6 | L26: 4.9 | M26: 4.4 | N26: =(L26*M26) -> 21.56 | R26: 4 | T26: 1.3 | U26: =AVERAGE(J26:J29) -> 8.35 | W26: =U26/T26 -> 6.4230769 | Y26: =MAX(J26:J29) -> 9.5 | Z26: =AVERAGE(K26:K29) -> 6 | AA26: =AVERAGE(L26:L29) -> 4.725 | AB26: =AVERAGE(M26:M29) -> 12.1 | AC26: =AVERAGE(N26:N29) -> 48.3 | AE26: PR | AF26: =SUM(N26:N29) -> 193.2 | AG26: =SUM(AS26:AS29) -> 64.66 | AH26: =SUM(BD26:BD28) -> 54.93 | AI26: 45.9 | AJ26: SD | AK26: 1.3 | AL26: 1.6 | AM26: 0.4 | AO26: 7.3 | AP26: 4.7 | AQ26: 4.3 | AR26: 6.4 | AS26: =(AQ26*AR26) -> 27.52 | AV26: 1.3 | AW26: 1.5 | AX26: 0.4 | AZ26: 10.8 | BA26: 9.7 | BB26: 5.9 | BC26: 6.9 | BD26: =(BB26*BC26) -> 40.71 | BF26: 1.7 | BG26: =AVERAGE(AZ26:AZ28) -> 5.5666667 | BI26: =(BG26/BF26) -> 3.2745098 | BK26: =MAX(AZ26:AZ28) -> 10.8 | BL26: =AVERAGE(BA26:BA28) -> 4.9 | BM26: =AVERAGE(BB26:BB28) -> 3.4 | BN26: =AVERAGE(BC26:BC28) -> 4.5 | BO26: =AVERAGE(BD26:BD28) -> 18.31 | BQ26: 1.7 | BR26: 2.5 | BS26: 0.6 | BU26: 12.7 | BV26: 10.3 | BW26: 7.4 | BX26: 6.2 | BY26: =(BW26*BX26) -> 45.88 | CB26: 1.6 | CC26: 2.4 | CD26: 0.6 | CJ26: 222 | CK26: 231 | CL26: 130 | CM26: 136
H27: 1 | I27: Gl. Submandibularis links | J27: 9.4 | K27: 7.4 | L27: 5.6 | M27: 9.3 | N27: =(L27*M27) -> 52.08 | P27: 1 | V27: Mittelwert | W27: =AVERAGE(W2:W26) -> 8.4661572 | AO27: 3.1 | AP27: 2.6 | AQ27: 1.9 | AR27: 4.2 | AS27: =(AQ27*AR27) -> 7.98 | AZ27: 3.2 | BA27: 2.7 | BB27: 2.2 | BC27: 3.6 | BD27: =(BB27*BC27) -> 7.92 | BU27: 0 | BV27: 0 | BW27: 0 | BX27: 0 | BY27: 0
H28: 1 | I28: Gl. Submandibularis rechts | J28: 9.1 | K28: 7 | L28: 5.6 | M28: 8 | N28: =(L28*M28) -> 44.8 | P28: 1 | R28: =AVERAGE(R2:R26) -> 3.8333333 | V28: Stabw | W28: =STDEV(W2:W26) -> 2.2861534 | AO28: 3.7 | AP28: 2.9 | AQ28: 2.2 | AR28: 5.4 | AS28: =(AQ28*AR28) -> 11.88 | AZ28: 2.7 | BA28: 2.3 | BB28: 2.1 | BC28: 3 | BD28: =(BB28*BC28) -> 6.3 | BH28: Mittelwert | BI28: =AVERAGE(BI2:BI26) -> 3.2261941 | BU28: 0 | BV28: 0 | BW28: 0 | BX28: 0 | BY28: 0 | CJ28: =AVERAGE(CJ2:CJ26) -> 218.5 | CK28: =AVERAGE(CK2:CK26) -> 225.5 | CL28: =AVERAGE(CL2:CL26) -> 135.33333 | CM28: =AVERAGE(CM2:CM26) -> 141.5
H29: 1 | I29: Pankreas | J29: 5.4 | K29: 4 | L29: 2.8 | M29: 26.7 | N29: =(L29*M29) -> 74.76 | P29: 1 | AO29: 2.4 | AP29: 1.5 | AQ29: 1.2 | AR29: 14.4 | AS29: =(AQ29*AR29) -> 17.28 | BH29: Stabw | BI29: =STDEV(BI2:BI26) -> 0.92753437 | BU29: nd | BV29: nd | BW29: nd | BX29: nd | BY29: nd
J30: per lesion | Y30: per patient | AZ30: per lesion | BK30: per patient
I31: Mittelwert | J31: =AVERAGE(J2:J29) -> 7.1695652 | K31: =AVERAGE(K2:K29) -> 4.9043478 | L31: =AVERAGE(L2:L29) -> 4.126087 | M31: =AVERAGE(M2:M29) -> 10.3 | N31: =AVERAGE(N2:N29) -> 45.107826 | X31: Mittelwert | Y31: =AVERAGE(Y2:Y29) -> 8.8 | Z31: =AVERAGE(Z2:Z29) -> 5.2178571 | AA31: =AVERAGE(AA2:AA29) -> 4.2446429 | AB31: =AVERAGE(AB2:AB29) -> 10.786905 | AC31: =AVERAGE(AC2:AC29) -> 44.15 | AY31: Mittelwert | AZ31: =AVERAGE(AZ2:AZ28) -> 5.7190476 | BA31: =AVERAGE(BA2:BA28) -> 4.4285714 | BB31: =AVERAGE(BB2:BB28) -> 3.5714286 | BC31: =AVERAGE(BC2:BC28) -> 8.2047619 | BD31: =AVERAGE(BD2:BD28) -> 29.574762 | BJ31: Mittelwert | BK31: =AVERAGE(BK2:BK26) -> 7.6333333 | BL31: =AVERAGE(BL2:BL26) -> 4.2282051 | BM31: =AVERAGE(BM2:BM26) -> 3.2402778 | BN31: =AVERAGE(BN2:BN26) -> 10.1 | BO31: =AVERAGE(BO2:BO26) -> 31.158333
I32: Max | J32: =MAX(J2:J29) -> 11.9 | K32: =MAX(K2:K29) -> 8.1 | L32: =MAX(L2:L29) -> 6.8 | M32: =MAX(M2:M29) -> 49.9 | N32: =MAX(N2:N29) -> 229.54 | X32: Max | Y32: =MAX(Y2:Y29) -> 11.9 | Z32: =MAX(Z2:Z29) -> 6.6 | AA32: =MAX(AA2:AA29) -> 5.2 | AB32: =MAX(AB2:AB29) -> 29.9 | AC32: =MAX(AC2:AC29) -> 110.63 | AY32: Max | AZ32: =MAX(AZ2:AZ28) -> 14.4 | BA32: =MAX(BA2:BA28) -> 10.3 | BB32: =MAX(BB2:BB28) -> 8.9 | BC32: =MAX(BC2:BC28) -> 37.6 | BD32: =MAX(BD2:BD28) -> 101.52 | BJ32: Max | BK32: =MAX(BK2:BK26) -> 14.4 | BL32: =MAX(BL2:BL26) -> 5.7 | BM32: =MAX(BM2:BM26) -> 4.8 | BN32: =MAX(BN2:BN26) -> 37.6 | BO32: =MAX(BO2:BO26) -> 101.52
I33: min | J33: =MIN(J2:J29) -> 2.6 | K33: =MIN(K2:K29) -> 1.4 | L33: =MIN(L2:L29) -> 1.9 | M33: =MIN(M2:M29) -> 1.1 | N33: =MIN(N2:N29) -> 2.31 | X33: min | Y33: =MIN(Y2:Y29) -> 5.7 | Z33: =MIN(Z2:Z29) -> 2.95 | AA33: =MIN(AA2:AA29) -> 2.7 | AB33: =MIN(AB2:AB29) -> 2.35 | AC33: =MIN(AC2:AC29) -> 5.89 | AY33: min | AZ33: =MIN(AZ2:AZ28) -> 2.5 | BA33: =MIN(BA2:BA28) -> 1.9 | BB33: =MIN(BB2:BB28) -> 2 | BC33: =MIN(BC2:BC28) -> 1 | BD33: =MIN(BD2:BD28) -> 2 | BJ33: min | BK33: =MIN(BK2:BK26) -> 3.6 | BL33: =MIN(BL2:BL26) -> 3 | BM33: =MIN(BM2:BM26) -> 2.55 | BN33: =MIN(BN2:BN26) -> 1.85 | BO33: =MIN(BO2:BO26) -> 4.725
I34: standardabweichung | J34: =_xlfn.STDEV.P(J2:J29) -> 2.799291 | K34: =_xlfn.STDEV.P(K2:K29) -> 2.0228001 | L34: =_xlfn.STDEV.P(L2:L29) -> 1.5800983 | M34: =_xlfn.STDEV.P(M2:M29) -> 12.047839 | N34: =_xlfn.STDEV.P(N2:N29) -> 54.668112 | X34: standardabweichung | Y34: =_xlfn.STDEV.P(Y2:Y29) -> 1.9756855 | Z34: =_xlfn.STDEV.P(Z2:Z29) -> 1.1694216 | AA34: =_xlfn.STDEV.P(AA2:AA29) -> 0.87543903 | AB34: =_xlfn.STDEV.P(AB2:AB29) -> 9.2677834 | AC34: =_xlfn.STDEV.P(AC2:AC29) -> 33.836066 | AY34: standardabweichung | AZ34: =STDEV(AZ2:AZ28) -> 3.4711121 | BA34: =STDEV(BA2:BA28) -> 2.6391557 | BB34: =STDEV(BB2:BB28) -> 1.9652335 | BC34: =STDEV(BC2:BC28) -> 10.834227 | BD34: =STDEV(BD2:BD28) -> 35.345251 | BJ34: standardabweichung | BK34: =STDEV(BK2:BK26) -> 4.3167889 | BL34: =STDEV(BL2:BL26) -> 1.0345587 | BM34: =STDEV(BM2:BM26) -> 0.85551181 | BN34: =STDEV(BN2:BN26) -> 13.669638 | BO34: =STDEV(BO2:BO26) -> 35.815199
A37: 7 | B37: Hos, Mete | C37: 26816 | D37: 43493 | E37: 43689 | F37: 43490 | G37: 43690 | H37: 1 | I37: links zervikal | J37: 0 | K37: 0 | L37: 0 | M37: 0 | N37: 0 | AO37: 0 | AP37: 0 | AQ37: 0 | AR37: 0 | AS37: 0 | AZ37: 11.8 | BA37: 7.6 | BB37: 7.6 | BC37: 0.8 | BD37: 6.1 | BF37: 1.4 | BG37: 0.6 | BH37: 2.2 | BU37: 8.5 | BV37: 5.2 | BW37: 4.8 | BX37: 2.3 | BY37: 11.1 | CB37: 1.3 | CC37: 0.7 | CD37: 2.1
H38: 1 | I38: links zervikal | J38: 0 | K38: 0 | L38: 0 | M38: 0 | N38: 0 | AO38: 0 | AP38: 0 | AQ38: 0 | AR38: 0 | AS38: 0 | AZ38: 4.1 | BA38: 3.2 | BB38: 2.6 | BC38: 2.1 | BD38: 5.5 | BU38: 3.8 | BV38: 2.9 | BW38: 2.4 | BX38: 4.2 | BY38: 10.2
B163: Thal, Hans-Günther | C163: 21814 | D163: 43528 | F163: 43537 | H163: 1 | I163: Aorta abdominalis | J163: 3.3 | K163: 2.6 | L163: 1.6 | M163: 78.8 | N163: =(L163*M163) -> 126.08 | T163: 1 | AK163: 1 | AL163: 1.1 | AM163: 0.5 | AZ163: 3.2 | BA163: 2.5 | BB163: 1.9 | BC163: 86.4 | BD163: =(BB163*BC163) -> 164.16 | BQ163: 1.4 | BR163: 0.5 | BS163: 2.2
B165: Kohles, Cathrin | C165: 30190 | D165: 43752 | F165: 43753 | H165: 1 | I165: links retroperitoneal | J165: 8.2 | K165: 6.5 | L165: 4.2 | M165: 45.5 | N165: =(L165*M165) -> 191.1 | T165: 1.3 | AK165: 1.3 | AL165: 1.3 | AM165: 0.7 | AZ165: 0 | BA165: 0 | BB165: 0 | BC165: 0 | BD165: 0 | BQ165: 1 | BR165: 0.5 | BS165: 1.8

Sheet Lungenfibrose
B1: Name | C1: Geburtsdatum | D1: Scandatum | E1: Indikation | F1: Datum 2. FAPI PET/CT
A2: 1 | B2: Stöltzel, Alexandra | C2: 26033 | D2: 43353 | E2: Systemische Sklerose/Lungenfibrose
A3: 2 | B3: Hauck, Michael | C3: 27806 | D3: 43437 | E3: Systemische Sklerose/Lungenfibrose
A4: 3 | B4: Hadi Issa, Intissar | C4: 24686 | D4: 43486 | E4: Systemische Sklerose/Lungenfibrose
A5: 4 | B5: Massing, Claudia | C5: 26532 | D5: 43500 | E5: Systemische Sklerose/Lungenfibrose
A6: 5 | B6: Häckl, Werner | C6: 21317 | D6: 43500 | E6: Kollagenose/Dermatomyositis/Lungenfibrose
A7: 6 | B7: Arnold, Markus | C7: 27243 | D7: 43500 | E7: Systemische Sklerose/Lungenfibrose/Sarkoidose
A8: 7 | B8: Morina, Sami | C8: 29587 | D8: 43507 | E8: Dermatomyositis/Lungenfibrose | F8: 43703
A9: 8 | B9: Sitzmann, Brigitte | C9: 20975 | D9: 43556 | E9: Systemische Sklerose/ Lungenfibrose
A10: 9 | B10: Bechmann, Stefan | C10: 24759 | D10: 43563 | E10: Systemische Sklerose/Lungenfibrose
A11: 10 | B11: Dotzler, Siegmund | C11: 22647 | D11: 43570 | E11: Systemische Sklerose/Lungenfibrose
A12: 11 | B12: Amslinger, Claudia | C12: 23143 | D12: 43640 | E12: Systemische Sklerose/Lungenfibrose
A13: 12 | B13: Gärtner, Hannelore | C13: 17945 | D13: 43654 | E13: Systemische Sklerose/Lungenfibrose
A14: 13 | B14: Prügner-Glaubitz, Michael | C14: 17637 | D14: 43675 | E14: Systemische Sklerose/Lungenfibrose
A15: 14 | B15: Hofmann, Martina | C15: 24558 | D15: 43675 | E15: Dermatomyositis/Lungenfibrose
A16: 15 | B16: Unkauf, Lieselotte | C16: 20056 | D16: 43682 | E16: Systemische Sklerose/Lungenfibrose
A17: 16 | B17: Dittrich, Rosemarie | C17: 17236 | D17: 43689 | E17: Systemische Sklerose/Lungenfibrose
A18: 17 | B18: Fuchs, Hans-Wolfgang | C18: 16505 | D18: 43696 | E18: Systemische Sklerose/Lungenfibrose
A19: 18 | B19: Schiller, Doris | C19: 23451 | D19: 43703 | E19: Systemische Sklerose/Lungenfibrose
A20: 19 | B20: Zenkel, Elfriede | C20: 14829 | D20: 43717 | E20: Systemische Sklerose/V.a. Lungenfibrose
... A30: 29 | B30: Metzler, Walter | C30: 16276 | D30: 44512 | E30: Lungenfibrose
A31: 30 | B31: Miletic, Maja | C31: 30474 | D31: 44494 | E31: Lungenfibrose | F31: 44729
A32: 31 | B32: Serby, Anneliese | C32: 16613 | D32: 44463 | E32: Lungenfibrose
A33: 32 | B33: Heidingsfelder, Jürgen | C33: 20385 | D33: 44456 | E33: Lungenfibrose
A34: 33 | B34: Schwab, Klaus | C34: 24709 | D34: 44414 | E34: Lungenfibrose
A35: 34 | B35: Hitz, Marianne | C35: 21592 | D35: 44396 | E35: Lungenfibrose
A36: 35 | B36: Eberlein, Olaf | C36: 21721 | D36: 44400 | E36: Lungenfibrose/Bronchialkarzinom
A37: 36 | B37: Dzelic, Emir | C37: 25971 | D37: 44383 | E37: Lungenfibrose
A38: 37 | B38: Thumshirn, Maria | C38: 15060 | D38: 44383 | E38: Lungenfibrose
A39: 38 | B39: Langgut, Katrin | C39: 19530 | D39: 44389 | E39: Lungenfibrose
A40: 39 | B40: Rollinger, Kerstin | C40: 25898 | D40: 44386 | E40: Lungenfibrose
A41: 40 | B41: Bauer, Andrea | C41: 21656 | D41: 44365 | E41: Lungenfibrose
A42: 41 | B42: Romanelli, Beniamo | C42: 27362 | D42: 44372 | E42: Lungenfibrose
A43: 42 | B43: Harnisch, Elke | C43: 20098 | D43: 44372 | E43: Lungenfibrose
... A54: 53 | B54: Stenger, Julian | C54: 34159 | D54: 44186 | E54: Systemische Sklerose/Lungenfibrose
